2025-03-17 12:31:28,988 - ERROR - Traceback (most recent call last):
  File "C:\Users\DBA01\.pyenv\pyenv-win\versions\3.12.3\Lib\asyncio\runners.py", line 194, in run
    return runner.run(main)
           ^^^^^^^^^^^^^^^^
  File "C:\Users\DBA01\.pyenv\pyenv-win\versions\3.12.3\Lib\asyncio\runners.py", line 118, in run
    return self._loop.run_until_complete(task)
           ^^^^^^^^^^^^^^^^^^^^^^^^^^^^^^^^^^^
  File "C:\Users\DBA01\.pyenv\pyenv-win\versions\3.12.3\Lib\asyncio\base_events.py", line 687, in run_until_complete
    return future.result()
           ^^^^^^^^^^^^^^^
  File "C:\Users\DBA01\Documents\FastAPI FC\fapi\venvfapi\Lib\site-packages\uvicorn\server.py", line 70, in serve
    await self._serve(sockets)
  File "C:\Users\DBA01\Documents\FastAPI FC\fapi\venvfapi\Lib\site-packages\uvicorn\server.py", line 85, in _serve
    await self.startup(sockets=sockets)
  File "C:\Users\DBA01\Documents\FastAPI FC\fapi\venvfapi\Lib\site-packages\uvicorn\server.py", line 135, in startup
    server = await loop.create_server(create_protocol, sock=sock, ssl=config.ssl, backlog=config.backlog)
             ^^^^^^^^^^^^^^^^^^^^^^^^^^^^^^^^^^^^^^^^^^^^^^^^^^^^^^^^^^^^^^^^^^^^^^^^^^^^^^^^^^^^^^^^^^^^
  File "C:\Users\DBA01\.pyenv\pyenv-win\versions\3.12.3\Lib\asyncio\base_events.py", line 1597, in create_server
    server._start_serving()
  File "C:\Users\DBA01\.pyenv\pyenv-win\versions\3.12.3\Lib\asyncio\base_events.py", line 317, in _start_serving
    sock.listen(self._backlog)
OSError: [WinError 10022] Foi fornecido um argumento inválido

During handling of the above exception, another exception occurred:

Traceback (most recent call last):
  File "C:\Users\DBA01\Documents\FastAPI FC\fapi\venvfapi\Lib\site-packages\starlette\routing.py", line 699, in lifespan
    await receive()
  File "C:\Users\DBA01\Documents\FastAPI FC\fapi\venvfapi\Lib\site-packages\uvicorn\lifespan\on.py", line 137, in receive
    return await self.receive_queue.get()
           ^^^^^^^^^^^^^^^^^^^^^^^^^^^^^^
  File "C:\Users\DBA01\.pyenv\pyenv-win\versions\3.12.3\Lib\asyncio\queues.py", line 158, in get
    await getter
asyncio.exceptions.CancelledError

2025-03-17 12:34:23,043 - ERROR - Traceback (most recent call last):
  File "C:\Users\DBA01\.pyenv\pyenv-win\versions\3.12.3\Lib\asyncio\runners.py", line 194, in run
    return runner.run(main)
           ^^^^^^^^^^^^^^^^
  File "C:\Users\DBA01\.pyenv\pyenv-win\versions\3.12.3\Lib\asyncio\runners.py", line 118, in run
    return self._loop.run_until_complete(task)
           ^^^^^^^^^^^^^^^^^^^^^^^^^^^^^^^^^^^
  File "C:\Users\DBA01\.pyenv\pyenv-win\versions\3.12.3\Lib\asyncio\base_events.py", line 674, in run_until_complete
    self.run_forever()
  File "C:\Users\DBA01\.pyenv\pyenv-win\versions\3.12.3\Lib\asyncio\base_events.py", line 641, in run_forever
    self._run_once()
  File "C:\Users\DBA01\.pyenv\pyenv-win\versions\3.12.3\Lib\asyncio\base_events.py", line 1987, in _run_once
    handle._run()
  File "C:\Users\DBA01\.pyenv\pyenv-win\versions\3.12.3\Lib\asyncio\events.py", line 88, in _run
    self._context.run(self._callback, *self._args)
  File "C:\Users\DBA01\Documents\FastAPI FC\fapi\venvfapi\Lib\site-packages\uvicorn\server.py", line 69, in serve
    with self.capture_signals():
  File "C:\Users\DBA01\.pyenv\pyenv-win\versions\3.12.3\Lib\contextlib.py", line 144, in __exit__
    next(self.gen)
  File "C:\Users\DBA01\Documents\FastAPI FC\fapi\venvfapi\Lib\site-packages\uvicorn\server.py", line 330, in capture_signals
    signal.raise_signal(captured_signal)
  File "C:\Users\DBA01\.pyenv\pyenv-win\versions\3.12.3\Lib\asyncio\runners.py", line 157, in _on_sigint
    raise KeyboardInterrupt()
KeyboardInterrupt

During handling of the above exception, another exception occurred:

Traceback (most recent call last):
  File "C:\Users\DBA01\Documents\FastAPI FC\fapi\venvfapi\Lib\site-packages\starlette\routing.py", line 699, in lifespan
    await receive()
  File "C:\Users\DBA01\Documents\FastAPI FC\fapi\venvfapi\Lib\site-packages\uvicorn\lifespan\on.py", line 137, in receive
    return await self.receive_queue.get()
           ^^^^^^^^^^^^^^^^^^^^^^^^^^^^^^
  File "C:\Users\DBA01\.pyenv\pyenv-win\versions\3.12.3\Lib\asyncio\queues.py", line 158, in get
    await getter
asyncio.exceptions.CancelledError

2025-03-17 12:34:23,043 - ERROR - Traceback (most recent call last):
  File "C:\Users\DBA01\.pyenv\pyenv-win\versions\3.12.3\Lib\asyncio\runners.py", line 194, in run
    return runner.run(main)
           ^^^^^^^^^^^^^^^^
  File "C:\Users\DBA01\.pyenv\pyenv-win\versions\3.12.3\Lib\asyncio\runners.py", line 118, in run
    return self._loop.run_until_complete(task)
           ^^^^^^^^^^^^^^^^^^^^^^^^^^^^^^^^^^^
  File "C:\Users\DBA01\.pyenv\pyenv-win\versions\3.12.3\Lib\asyncio\base_events.py", line 674, in run_until_complete
    self.run_forever()
  File "C:\Users\DBA01\.pyenv\pyenv-win\versions\3.12.3\Lib\asyncio\base_events.py", line 641, in run_forever
    self._run_once()
  File "C:\Users\DBA01\.pyenv\pyenv-win\versions\3.12.3\Lib\asyncio\base_events.py", line 1987, in _run_once
    handle._run()
  File "C:\Users\DBA01\.pyenv\pyenv-win\versions\3.12.3\Lib\asyncio\events.py", line 88, in _run
    self._context.run(self._callback, *self._args)
  File "C:\Users\DBA01\Documents\FastAPI FC\fapi\venvfapi\Lib\site-packages\uvicorn\server.py", line 69, in serve
    with self.capture_signals():
  File "C:\Users\DBA01\.pyenv\pyenv-win\versions\3.12.3\Lib\contextlib.py", line 144, in __exit__
    next(self.gen)
  File "C:\Users\DBA01\Documents\FastAPI FC\fapi\venvfapi\Lib\site-packages\uvicorn\server.py", line 330, in capture_signals
    signal.raise_signal(captured_signal)
  File "C:\Users\DBA01\.pyenv\pyenv-win\versions\3.12.3\Lib\asyncio\runners.py", line 157, in _on_sigint
    raise KeyboardInterrupt()
KeyboardInterrupt

During handling of the above exception, another exception occurred:

Traceback (most recent call last):
  File "C:\Users\DBA01\Documents\FastAPI FC\fapi\venvfapi\Lib\site-packages\starlette\routing.py", line 699, in lifespan
    await receive()
  File "C:\Users\DBA01\Documents\FastAPI FC\fapi\venvfapi\Lib\site-packages\uvicorn\lifespan\on.py", line 137, in receive
    return await self.receive_queue.get()
           ^^^^^^^^^^^^^^^^^^^^^^^^^^^^^^
  File "C:\Users\DBA01\.pyenv\pyenv-win\versions\3.12.3\Lib\asyncio\queues.py", line 158, in get
    await getter
asyncio.exceptions.CancelledError

2025-03-17 12:34:23,043 - ERROR - Traceback (most recent call last):
  File "C:\Users\DBA01\.pyenv\pyenv-win\versions\3.12.3\Lib\asyncio\runners.py", line 194, in run
    return runner.run(main)
           ^^^^^^^^^^^^^^^^
  File "C:\Users\DBA01\.pyenv\pyenv-win\versions\3.12.3\Lib\asyncio\runners.py", line 118, in run
    return self._loop.run_until_complete(task)
           ^^^^^^^^^^^^^^^^^^^^^^^^^^^^^^^^^^^
  File "C:\Users\DBA01\.pyenv\pyenv-win\versions\3.12.3\Lib\asyncio\base_events.py", line 674, in run_until_complete
    self.run_forever()
  File "C:\Users\DBA01\.pyenv\pyenv-win\versions\3.12.3\Lib\asyncio\base_events.py", line 641, in run_forever
    self._run_once()
  File "C:\Users\DBA01\.pyenv\pyenv-win\versions\3.12.3\Lib\asyncio\base_events.py", line 1987, in _run_once
    handle._run()
  File "C:\Users\DBA01\.pyenv\pyenv-win\versions\3.12.3\Lib\asyncio\events.py", line 88, in _run
    self._context.run(self._callback, *self._args)
  File "C:\Users\DBA01\Documents\FastAPI FC\fapi\venvfapi\Lib\site-packages\uvicorn\server.py", line 69, in serve
    with self.capture_signals():
  File "C:\Users\DBA01\.pyenv\pyenv-win\versions\3.12.3\Lib\contextlib.py", line 144, in __exit__
    next(self.gen)
  File "C:\Users\DBA01\Documents\FastAPI FC\fapi\venvfapi\Lib\site-packages\uvicorn\server.py", line 330, in capture_signals
    signal.raise_signal(captured_signal)
  File "C:\Users\DBA01\.pyenv\pyenv-win\versions\3.12.3\Lib\asyncio\runners.py", line 157, in _on_sigint
    raise KeyboardInterrupt()
KeyboardInterrupt

During handling of the above exception, another exception occurred:

Traceback (most recent call last):
  File "C:\Users\DBA01\Documents\FastAPI FC\fapi\venvfapi\Lib\site-packages\starlette\routing.py", line 699, in lifespan
    await receive()
  File "C:\Users\DBA01\Documents\FastAPI FC\fapi\venvfapi\Lib\site-packages\uvicorn\lifespan\on.py", line 137, in receive
    return await self.receive_queue.get()
           ^^^^^^^^^^^^^^^^^^^^^^^^^^^^^^
  File "C:\Users\DBA01\.pyenv\pyenv-win\versions\3.12.3\Lib\asyncio\queues.py", line 158, in get
    await getter
asyncio.exceptions.CancelledError

